<?xml version="1.0" ?>
<robot name="stationary_ai">
  <!-- trossen_black -->
  <!-- maple_tabletop -->
  <!-- wxai -->
  <material name="trossen_black">
    <texture filename="package://trossen_arm_description/meshes/trossen_black.png"/>
  </material>
  <material name="maple_tabletop">
    <texture filename="package://trossen_arm_description/meshes/maple_tabletop.png"/>
  </material>
  <link name="tabletop_link">
    <inertial>
      <origin rpy="0 0 0" xyz="0 0 0"/>
      <mass value="10.0"/>
      <inertia ixx="0.1" ixy="0.0" ixz="0.0" iyy="0.1" iyz="0.0" izz="0.1"/>
    </inertial>
    <visual>
      <origin rpy="0 0 0" xyz="0 0 0"/>
      <geometry>
        <mesh filename="package://trossen_arm_description/meshes/stationary_ai/tabletop_link.stl"/>
      </geometry>
      <material name="maple_tabletop"/>
    </visual>
    <collision>
      <origin rpy="0 0 0" xyz="0 0 0"/>
      <geometry>
        <mesh filename="package://trossen_arm_description/meshes/stationary_ai/tabletop_link.stl"/>
      </geometry>
    </collision>
  </link>
  <link name="frame_link">
    <inertial>
      <origin rpy="0 0 0" xyz="0 0 0"/>
      <mass value="5.0"/>
      <inertia ixx="0.05" ixy="0.0" ixz="0.0" iyy="0.05" iyz="0.0" izz="0.05"/>
    </inertial>
    <visual>
      <origin rpy="0 0 0" xyz="0 0 0"/>
      <geometry>
        <mesh filename="package://trossen_arm_description/meshes/stationary_ai/frame_link.stl"/>
      </geometry>
      <material name="trossen_black"/>
    </visual>
    <collision>
      <origin rpy="0 0 0" xyz="0 0 0"/>
      <geometry>
        <mesh filename="package://trossen_arm_description/meshes/stationary_ai/frame_link.stl"/>
      </geometry>
    </collision>
  </link>
  <joint name="frame_joint" type="fixed">
    <origin rpy="0 0 0" xyz="0.0 0.0 0.02"/>
    <parent link="tabletop_link"/>
    <child link="frame_link"/>
  </joint>
  <link name="cam_high_mount_link">
    <inertial>
      <origin rpy="0 0 0" xyz="0 0 0"/>
      <mass value="0.1"/>
      <inertia ixx="0.001" ixy="0.0" ixz="0.0" iyy="0.001" iyz="0.0" izz="0.001"/>
    </inertial>
    <visual>
      <origin rpy="0 0 0" xyz="0 0 0"/>
      <geometry>
        <mesh filename="package://trossen_arm_description/meshes/stationary_ai/cam_high_mount_link.stl"/>
      </geometry>
      <material name="trossen_black"/>
    </visual>
    <collision>
      <origin rpy="0 0 0" xyz="0 0 0"/>
      <geometry>
        <mesh filename="package://trossen_arm_description/meshes/stationary_ai/cam_high_mount_link.stl"/>
      </geometry>
    </collision>
  </link>
  <joint name="cam_high_mount_joint" type="fixed">
    <origin rpy="-3.141592653589793 0.0 1.5707963267948966" xyz="-0.401982 -0.040000 1.059852"/>
    <parent link="frame_link"/>
    <child link="cam_high_mount_link"/>
  </joint>
  <!-- camera body, with origin at bottom screw mount -->
  <joint name="cam_high_joint" type="fixed">
    <origin rpy="0 1.1344640137963142 0" xyz="-0.348293 -0.000000 1.028733"/>
    <parent link="frame_link"/>
    <child link="cam_high_bottom_screw_frame"/>
  </joint>
  <link name="cam_high_bottom_screw_frame"/>
  <joint name="cam_high_link_joint" type="fixed">
    <origin rpy="0 0 0" xyz="0.01085 0.009 0.021"/>
    <parent link="cam_high_bottom_screw_frame"/>
    <child link="cam_high_link"/>
  </joint>
  <link name="cam_high_link">
    <visual>
      <!-- the mesh origin is at front plate in between the two infrared camera axes -->
      <origin rpy="1.5707963267948966 0 1.5707963267948966" xyz="0.0038 -0.009 0"/>
      <geometry>
        <mesh filename="package://trossen_arm_description/meshes/peripherals/d405.stl" scale="0.001 0.001 0.001"/>
      </geometry>
      <material name="aluminum">
        <color rgba="0.5 0.5 0.5 1"/>
      </material>
    </visual>
    <collision>
      <origin rpy="0 0 0" xyz="-0.0078 -0.009 0"/>
      <geometry>
        <box size="0.023 0.042 0.042"/>
      </geometry>
    </collision>
    <inertial>
      <!-- The following are not reliable values, and should not be used for modeling -->
      <mass value="0.072"/>
      <origin xyz="0 0 0"/>
      <inertia ixx="0.00002117" ixy="0.0" ixz="0.0" iyy="0.000013758" iyz="0.0" izz="0.000013758"/>
    </inertial>
  </link>
  <!-- camera depth joints and links -->
  <joint name="cam_high_depth_joint" type="fixed">
    <origin rpy="0 0 0" xyz="0 0 0"/>
    <parent link="cam_high_link"/>
    <child link="cam_high_depth_frame"/>
  </joint>
  <link name="cam_high_depth_frame"/>
  <joint name="cam_high_depth_optical_joint" type="fixed">
    <origin rpy="-1.5707963267948966 0 -1.5707963267948966" xyz="0 0 0"/>
    <parent link="cam_high_depth_frame"/>
    <child link="cam_high_depth_optical_frame"/>
  </joint>
  <link name="cam_high_depth_optical_frame"/>
  <!-- camera left IR joints and links -->
  <joint name="cam_high_infra1_joint" type="fixed">
    <origin rpy="0 0 0" xyz="0 0.0 0"/>
    <parent link="cam_high_link"/>
    <child link="cam_high_infra1_frame"/>
  </joint>
  <link name="cam_high_infra1_frame"/>
  <joint name="cam_high_infra1_optical_joint" type="fixed">
    <origin rpy="-1.5707963267948966 0 -1.5707963267948966" xyz="0 0 0"/>
    <parent link="cam_high_infra1_frame"/>
    <child link="cam_high_infra1_optical_frame"/>
  </joint>
  <link name="cam_high_infra1_optical_frame"/>
  <!-- camera right IR joints and links -->
  <joint name="cam_high_infra2_joint" type="fixed">
    <origin rpy="0 0 0" xyz="0 -0.018 0"/>
    <parent link="cam_high_link"/>
    <child link="cam_high_infra2_frame"/>
  </joint>
  <link name="cam_high_infra2_frame"/>
  <joint name="cam_high_infra2_optical_joint" type="fixed">
    <origin rpy="-1.5707963267948966 0 -1.5707963267948966" xyz="0 0 0"/>
    <parent link="cam_high_infra2_frame"/>
    <child link="cam_high_infra2_optical_frame"/>
  </joint>
  <link name="cam_high_infra2_optical_frame"/>
  <!-- camera color joints and links -->
  <joint name="cam_high_color_joint" type="fixed">
    <origin rpy="0 0 0" xyz="0 0.0 0"/>
    <parent link="cam_high_link"/>
    <child link="cam_high_color_frame"/>
  </joint>
  <link name="cam_high_color_frame"/>
  <joint name="cam_high_color_optical_joint" type="fixed">
    <origin rpy="-1.5707963267948966 0 -1.5707963267948966" xyz="0 0 0"/>
    <parent link="cam_high_color_frame"/>
    <child link="cam_high_color_optical_frame"/>
  </joint>
  <link name="cam_high_color_optical_frame"/>
  <link name="cam_low_mount_link">
    <inertial>
      <origin rpy="0 0 0" xyz="0 0 0"/>
      <mass value="0.1"/>
      <inertia ixx="0.001" ixy="0.0" ixz="0.0" iyy="0.001" iyz="0.0" izz="0.001"/>
    </inertial>
    <visual>
      <origin rpy="0 0 0" xyz="0 0 0"/>
      <geometry>
        <mesh filename="package://trossen_arm_description/meshes/stationary_ai/cam_low_mount_link.stl"/>
      </geometry>
      <material name="trossen_black"/>
    </visual>
    <collision>
      <origin rpy="0 0 0" xyz="0 0 0"/>
      <geometry>
        <mesh filename="package://trossen_arm_description/meshes/stationary_ai/cam_low_mount_link.stl"/>
      </geometry>
    </collision>
  </link>
  <joint name="cam_low_mount_joint" type="fixed">
    <origin rpy="-3.141592653589793 0.0 1.5707963267948966" xyz="-0.415000 -0.024884 0.044061"/>
    <parent link="frame_link"/>
    <child link="cam_low_mount_link"/>
  </joint>
  <!-- camera body, with origin at bottom screw mount -->
  <joint name="cam_low_joint" type="fixed">
    <origin rpy="0 -0.09599310885968812 0" xyz="-0.389324 0.000000 0.010132"/>
    <parent link="frame_link"/>
    <child link="cam_low_bottom_screw_frame"/>
  </joint>
  <link name="cam_low_bottom_screw_frame"/>
  <joint name="cam_low_link_joint" type="fixed">
    <origin rpy="0 0 0" xyz="0.01085 0.009 0.021"/>
    <parent link="cam_low_bottom_screw_frame"/>
    <child link="cam_low_link"/>
  </joint>
  <link name="cam_low_link">
    <visual>
      <!-- the mesh origin is at front plate in between the two infrared camera axes -->
      <origin rpy="1.5707963267948966 0 1.5707963267948966" xyz="0.0038 -0.009 0"/>
      <geometry>
        <mesh filename="package://trossen_arm_description/meshes/peripherals/d405.stl" scale="0.001 0.001 0.001"/>
      </geometry>
      <material name="aluminum">
        <color rgba="0.5 0.5 0.5 1"/>
      </material>
    </visual>
    <collision>
      <origin rpy="0 0 0" xyz="-0.0078 -0.009 0"/>
      <geometry>
        <box size="0.023 0.042 0.042"/>
      </geometry>
    </collision>
    <inertial>
      <!-- The following are not reliable values, and should not be used for modeling -->
      <mass value="0.072"/>
      <origin xyz="0 0 0"/>
      <inertia ixx="0.00002117" ixy="0.0" ixz="0.0" iyy="0.000013758" iyz="0.0" izz="0.000013758"/>
    </inertial>
  </link>
  <!-- camera depth joints and links -->
  <joint name="cam_low_depth_joint" type="fixed">
    <origin rpy="0 0 0" xyz="0 0 0"/>
    <parent link="cam_low_link"/>
    <child link="cam_low_depth_frame"/>
  </joint>
  <link name="cam_low_depth_frame"/>
  <joint name="cam_low_depth_optical_joint" type="fixed">
    <origin rpy="-1.5707963267948966 0 -1.5707963267948966" xyz="0 0 0"/>
    <parent link="cam_low_depth_frame"/>
    <child link="cam_low_depth_optical_frame"/>
  </joint>
  <link name="cam_low_depth_optical_frame"/>
  <!-- camera left IR joints and links -->
  <joint name="cam_low_infra1_joint" type="fixed">
    <origin rpy="0 0 0" xyz="0 0.0 0"/>
    <parent link="cam_low_link"/>
    <child link="cam_low_infra1_frame"/>
  </joint>
  <link name="cam_low_infra1_frame"/>
  <joint name="cam_low_infra1_optical_joint" type="fixed">
    <origin rpy="-1.5707963267948966 0 -1.5707963267948966" xyz="0 0 0"/>
    <parent link="cam_low_infra1_frame"/>
    <child link="cam_low_infra1_optical_frame"/>
  </joint>
  <link name="cam_low_infra1_optical_frame"/>
  <!-- camera right IR joints and links -->
  <joint name="cam_low_infra2_joint" type="fixed">
    <origin rpy="0 0 0" xyz="0 -0.018 0"/>
    <parent link="cam_low_link"/>
    <child link="cam_low_infra2_frame"/>
  </joint>
  <link name="cam_low_infra2_frame"/>
  <joint name="cam_low_infra2_optical_joint" type="fixed">
    <origin rpy="-1.5707963267948966 0 -1.5707963267948966" xyz="0 0 0"/>
    <parent link="cam_low_infra2_frame"/>
    <child link="cam_low_infra2_optical_frame"/>
  </joint>
  <link name="cam_low_infra2_optical_frame"/>
  <!-- camera color joints and links -->
  <joint name="cam_low_color_joint" type="fixed">
    <origin rpy="0 0 0" xyz="0 0.0 0"/>
    <parent link="cam_low_link"/>
    <child link="cam_low_color_frame"/>
  </joint>
  <link name="cam_low_color_frame"/>
  <joint name="cam_low_color_optical_joint" type="fixed">
    <origin rpy="-1.5707963267948966 0 -1.5707963267948966" xyz="0 0 0"/>
    <parent link="cam_low_color_frame"/>
    <child link="cam_low_color_optical_frame"/>
  </joint>
  <link name="cam_low_color_optical_frame"/>
  <joint name="follower_left_mount_joint" type="fixed">
    <origin rpy="0 0 -1.5707963267948966" xyz="-0.019982 0.457500 0.019086"/>
    <parent link="frame_link"/>
    <child link="follower_left_base_link"/>
  </joint>
  <ros2_control name="TrossenArmHardwareInterface" type="system">
    <hardware>
      <plugin>mock_components/GenericSystem</plugin>
      <!-- ros2_control_hardware_type == 'mock_components' -->
      <!-- ros2_control_hardware_type == 'real' -->
    </hardware>
    <joint name="follower_left_joint_0">
      <command_interface name="position"/>
      <command_interface name="velocity"/>
      <command_interface name="external_effort"/>
      <state_interface name="position">
        <param name="initial_value">0.0</param>
      </state_interface>
      <state_interface name="velocity">
        <param name="initial_value">0.0</param>
      </state_interface>
      <state_interface name="effort">
        <param name="initial_value">0.0</param>
      </state_interface>
    </joint>
    <joint name="follower_left_joint_1">
      <command_interface name="position"/>
      <command_interface name="velocity"/>
      <command_interface name="external_effort"/>
      <state_interface name="position">
        <param name="initial_value">0.0</param>
      </state_interface>
      <state_interface name="velocity">
        <param name="initial_value">0.0</param>
      </state_interface>
      <state_interface name="effort">
        <param name="initial_value">0.0</param>
      </state_interface>
    </joint>
    <joint name="follower_left_joint_2">
      <command_interface name="position"/>
      <command_interface name="velocity"/>
      <command_interface name="external_effort"/>
      <state_interface name="position">
        <param name="initial_value">0.0</param>
      </state_interface>
      <state_interface name="velocity">
        <param name="initial_value">0.0</param>
      </state_interface>
      <state_interface name="effort">
        <param name="initial_value">0.0</param>
      </state_interface>
    </joint>
    <joint name="follower_left_joint_3">
      <command_interface name="position"/>
      <command_interface name="velocity"/>
      <command_interface name="external_effort"/>
      <state_interface name="position">
        <param name="initial_value">0.0</param>
      </state_interface>
      <state_interface name="velocity">
        <param name="initial_value">0.0</param>
      </state_interface>
      <state_interface name="effort">
        <param name="initial_value">0.0</param>
      </state_interface>
    </joint>
    <joint name="follower_left_joint_4">
      <command_interface name="position"/>
      <command_interface name="velocity"/>
      <command_interface name="external_effort"/>
      <state_interface name="position">
        <param name="initial_value">0.0</param>
      </state_interface>
      <state_interface name="velocity">
        <param name="initial_value">0.0</param>
      </state_interface>
      <state_interface name="effort">
        <param name="initial_value">0.0</param>
      </state_interface>
    </joint>
    <joint name="follower_left_joint_5">
      <command_interface name="position"/>
      <command_interface name="velocity"/>
      <command_interface name="external_effort"/>
      <state_interface name="position">
        <param name="initial_value">0.0</param>
      </state_interface>
      <state_interface name="velocity">
        <param name="initial_value">0.0</param>
      </state_interface>
      <state_interface name="effort">
        <param name="initial_value">0.0</param>
      </state_interface>
    </joint>
    <joint name="follower_left_left_carriage_joint">
      <command_interface name="position"/>
      <command_interface name="velocity"/>
      <command_interface name="external_effort"/>
      <state_interface name="position">
        <param name="initial_value">0.0</param>
      </state_interface>
      <state_interface name="velocity">
        <param name="initial_value">0.0</param>
      </state_interface>
      <state_interface name="effort">
        <param name="initial_value">0.0</param>
      </state_interface>
    </joint>
  </ros2_control>
  <link name="follower_left_base_link">
    <inertial>
      <origin rpy="0 0 0" xyz="-0.00014175 -0.00005228 0.03175177"/>
      <mass value="0.45969858"/>
      <inertia ixx="0.00041660" ixy="0.00000011" ixz="-0.00000454" iyy="0.00044896" iyz="-0.00000078" izz="0.00021403"/>
    </inertial>
    <visual>
      <origin rpy="0 0 0" xyz="0 0 0"/>
      <geometry>
        <mesh filename="package://trossen_arm_description/meshes/wxai/base_link.stl"/>
      </geometry>
      <material name="trossen_black"/>
    </visual>
    <collision>
      <origin rpy="0 0 0" xyz="0 0 0"/>
      <geometry>
        <mesh filename="package://trossen_arm_description/meshes/wxai/base_link.stl"/>
      </geometry>
    </collision>
  </link>
  <link name="follower_left_link_1">
    <inertial>
      <origin rpy="0 0 0" xyz="-0.00011075 0.00171176 0.02044592"/>
      <mass value="0.15270428"/>
      <inertia ixx="0.00018509" ixy="-0.00000191" ixz="-0.00001436" iyy="0.00008358" iyz="-0.00000130" izz="0.00019219"/>
    </inertial>
    <visual>
      <origin rpy="0 0 0" xyz="0 0 0"/>
      <geometry>
        <mesh filename="package://trossen_arm_description/meshes/wxai/link_1.stl"/>
      </geometry>
      <material name="trossen_black"/>
    </visual>
    <collision>
      <origin rpy="0 0 0" xyz="0 0 0"/>
      <geometry>
        <mesh filename="package://trossen_arm_description/meshes/wxai/link_1.stl"/>
      </geometry>
    </collision>
  </link>
  <joint name="follower_left_joint_0" type="revolute">
    <origin rpy="0 0 0" xyz="0 0 0.05725"/>
    <parent link="follower_left_base_link"/>
    <child link="follower_left_link_1"/>
    <axis xyz="0 0 1"/>
    <limit effort="27.0" lower="-3.0543261909900767" upper="3.0543261909900767" velocity="3.375"/>
  </joint>
  <link name="follower_left_link_2">
    <inertial>
      <origin rpy="0 0 0" xyz="-0.13121451 -0.00292583 0.00021345"/>
      <mass value="1.15316319"/>
      <inertia ixx="0.00102632" ixy="-0.00000319" ixz="-0.00002679" iyy="0.01736118" iyz="-0.00000193" izz="0.01794489"/>
    </inertial>
    <visual>
      <origin rpy="0 0 0" xyz="0 0 0"/>
      <geometry>
        <mesh filename="package://trossen_arm_description/meshes/wxai/link_2.stl"/>
      </geometry>
      <material name="trossen_black"/>
    </visual>
    <collision>
      <origin rpy="0 0 0" xyz="0 0 0"/>
      <geometry>
        <mesh filename="package://trossen_arm_description/meshes/wxai/link_2.stl"/>
      </geometry>
    </collision>
  </link>
  <joint name="follower_left_joint_1" type="revolute">
    <origin rpy="0 0 0" xyz="0.02 0 0.04625"/>
    <parent link="follower_left_link_1"/>
    <child link="follower_left_link_2"/>
    <axis xyz="0 1 0"/>
    <limit effort="27.0" lower="0.0" upper="3.141592653589793" velocity="3.375"/>
  </joint>
  <link name="follower_left_link_3">
    <inertial>
      <origin rpy="0 0 0" xyz="0.18083602 -0.00094090 0.05554937"/>
      <mass value="0.68666638"/>
      <inertia ixx="0.00064876" ixy="0.00009128" ixz="-0.00052002" iyy="0.00547407" iyz="0.00001159" izz="0.00561509"/>
    </inertial>
    <visual>
      <origin rpy="0 0 0" xyz="0 0 0"/>
      <geometry>
        <mesh filename="package://trossen_arm_description/meshes/wxai/link_3.stl"/>
      </geometry>
      <material name="trossen_black"/>
    </visual>
    <collision>
      <origin rpy="0 0 0" xyz="0 0 0"/>
      <geometry>
        <mesh filename="package://trossen_arm_description/meshes/wxai/link_3.stl"/>
      </geometry>
    </collision>
  </link>
  <joint name="follower_left_joint_2" type="revolute">
    <origin rpy="0 0 0" xyz="-0.264 0 0"/>
    <parent link="follower_left_link_2"/>
    <child link="follower_left_link_3"/>
    <axis xyz="0 -1 0"/>
    <limit effort="27.0" lower="0.0" upper="2.356194490192345" velocity="3.375"/>
  </joint>
  <link name="follower_left_link_4">
    <inertial>
      <origin rpy="0 0 0" xyz="0.05797842 0.00027145 0.05884447"/>
      <mass value="0.45789905"/>
      <inertia ixx="0.00053839" ixy="0.00000690" ixz="-0.00018164" iyy="0.00066138" iyz="0.00000724" izz="0.00042116"/>
    </inertial>
    <visual>
      <origin rpy="0 0 0" xyz="0 0 0"/>
      <geometry>
        <mesh filename="package://trossen_arm_description/meshes/wxai/link_4.stl"/>
      </geometry>
      <material name="trossen_black"/>
    </visual>
    <collision>
      <origin rpy="0 0 0" xyz="0 0 0"/>
      <geometry>
        <mesh filename="package://trossen_arm_description/meshes/wxai/link_4.stl"/>
      </geometry>
    </collision>
  </link>
  <joint name="follower_left_joint_3" type="revolute">
    <origin rpy="0 0 0" xyz="0.245 0 0.06"/>
    <parent link="follower_left_link_3"/>
    <child link="follower_left_link_4"/>
    <axis xyz="0 -1 0"/>
    <limit effort="7.0" lower="-1.5707963267948966" upper="1.5707963267948966" velocity="7.0"/>
  </joint>
  <link name="follower_left_link_5">
    <inertial>
      <origin rpy="0 0 0" xyz="0.00412447 -0.00001138 -0.04283184"/>
      <mass value="0.36693910"/>
      <inertia ixx="0.00018912" ixy="-0.00000045" ixz="0.00000090" iyy="0.00032062" iyz="0.00000003" izz="0.00026750"/>
    </inertial>
    <visual>
      <origin rpy="0 0 0" xyz="0 0 0"/>
      <geometry>
        <mesh filename="package://trossen_arm_description/meshes/wxai/link_5.stl"/>
      </geometry>
      <material name="trossen_black"/>
    </visual>
    <collision>
      <origin rpy="0 0 0" xyz="0 0 0"/>
      <geometry>
        <mesh filename="package://trossen_arm_description/meshes/wxai/link_5.stl"/>
      </geometry>
    </collision>
  </link>
  <joint name="follower_left_joint_4" type="revolute">
    <origin rpy="0 0 0" xyz="0.06775 0 0.0455"/>
    <parent link="follower_left_link_4"/>
    <child link="follower_left_link_5"/>
    <axis xyz="0 0 -1"/>
    <limit effort="7.0" lower="-1.5707963267948966" upper="1.5707963267948966" velocity="7.0"/>
  </joint>
  <link name="follower_left_link_6">
    <inertial>
      <origin rpy="0 0 0" xyz="0.04572768 -0.00000726 0.00001402"/>
      <mass value="0.55469347"/>
      <inertia ixx="0.00082429" ixy="-0.00000051" ixz="0.00000010" iyy="0.00048759" iyz="0.00000004" izz="0.00108600"/>
    </inertial>
    <visual>
      <origin rpy="0 0 0" xyz="0 0 0"/>
      <geometry>
        <mesh filename="package://trossen_arm_description/meshes/wxai/link_6.stl"/>
      </geometry>
      <material name="trossen_black"/>
    </visual>
    <collision>
      <origin rpy="0 0 0" xyz="0 0 0"/>
      <geometry>
        <mesh filename="package://trossen_arm_description/meshes/wxai/link_6.stl"/>
      </geometry>
    </collision>
  </link>
  <joint name="follower_left_joint_5" type="revolute">
    <origin rpy="0 0 0" xyz="0.02895 0 -0.0455"/>
    <parent link="follower_left_link_5"/>
    <child link="follower_left_link_6"/>
    <axis xyz="1 0 0"/>
    <limit effort="7.0" lower="-3.141592653589793" upper="3.141592653589793" velocity="7.0"/>
  </joint>
  <link name="follower_left_carriage_right">
    <inertial>
      <origin rpy="0 0 0" xyz="-0.00889602 0.00403514 0.00457901"/>
      <mass value="0.05036313"/>
      <inertia ixx="0.00001736" ixy="-0.00000165" ixz="-0.00000104" iyy="0.00000591" iyz="-0.00000172" izz="0.00001378"/>
    </inertial>
    <visual>
      <origin rpy="0 0 0" xyz="0 0 0"/>
      <geometry>
        <mesh filename="package://trossen_arm_description/meshes/wxai/carriage_right.stl"/>
      </geometry>
      <material name="trossen_black"/>
    </visual>
    <collision>
      <origin rpy="0 0 0" xyz="0 0 0"/>
      <geometry>
        <mesh filename="package://trossen_arm_description/meshes/wxai/carriage_right.stl"/>
      </geometry>
    </collision>
  </link>
  <joint name="follower_left_right_carriage_joint" type="prismatic">
    <origin rpy="0 0 0" xyz="0.0865 -0.023 0"/>
    <parent link="follower_left_link_6"/>
    <child link="follower_left_carriage_right"/>
    <mimic joint="follower_left_left_carriage_joint"/>
    <axis xyz="0 -1 0"/>
    <limit effort="400.0" lower="0.0" upper="0.044" velocity="0.0875"/>
  </joint>
  <link name="follower_left_carriage_left">
    <inertial>
      <origin rpy="0 0 0" xyz="-0.00889602 -0.00403515 -0.00457908"/>
      <mass value="0.05036313"/>
      <inertia ixx="0.00001736" ixy="-0.00000165" ixz="-0.00000104" iyy="0.00000591" iyz="-0.00000172" izz="0.00001378"/>
    </inertial>
    <visual>
      <origin rpy="0 0 0" xyz="0 0 0"/>
      <geometry>
        <mesh filename="package://trossen_arm_description/meshes/wxai/carriage_left.stl"/>
      </geometry>
      <material name="trossen_black"/>
    </visual>
    <collision>
      <origin rpy="0 0 0" xyz="0 0 0"/>
      <geometry>
        <mesh filename="package://trossen_arm_description/meshes/wxai/carriage_left.stl"/>
      </geometry>
    </collision>
  </link>
  <joint name="follower_left_left_carriage_joint" type="prismatic">
    <origin rpy="0 0 0" xyz="0.0865 0.023 0"/>
    <parent link="follower_left_link_6"/>
    <child link="follower_left_carriage_left"/>
    <axis xyz="0 1 0"/>
    <limit effort="400.0" lower="0.0" upper="0.044" velocity="0.0875"/>
  </joint>
  <link name="follower_left_camera_mount_d405">
    <inertial>
      <origin rpy="0 0 0" xyz="0.03023383 0.00679835 0.05006687"/>
      <mass value="0.04518012"/>
      <inertia ixx="0.00003426" ixy="-0.00000027" ixz="-0.00000309" iyy="0.00001980" iyz="-0.00000319" izz="0.00002470"/>
    </inertial>
    <visual>
      <origin rpy="0 0 0" xyz="0 0 0"/>
      <geometry>
        <mesh filename="package://trossen_arm_description/meshes/wxai/camera_mount_d405.stl"/>
      </geometry>
      <material name="trossen_black"/>
    </visual>
    <collision>
      <origin rpy="0 0 0" xyz="0 0 0"/>
      <geometry>
        <mesh filename="package://trossen_arm_description/meshes/wxai/camera_mount_d405.stl"/>
      </geometry>
    </collision>
  </link>
  <joint name="follower_left_camera_mount_joint" type="fixed">
    <origin rpy="0 0 0" xyz="0.012 0 0"/>
    <parent link="follower_left_link_6"/>
    <child link="follower_left_camera_mount_d405"/>
  </joint>
  <!-- camera body, with origin at bottom screw mount -->
  <joint name="follower_left_camera_joint" type="fixed">
    <origin rpy="0 0.3490658503988659 0" xyz="0.02927207801 0 0.03824951197"/>
    <parent link="follower_left_camera_mount_d405"/>
    <child link="follower_left_camera_bottom_screw_frame"/>
  </joint>
  <link name="follower_left_camera_bottom_screw_frame"/>
  <joint name="follower_left_camera_link_joint" type="fixed">
    <origin rpy="0 0 0" xyz="0.01085 0.009 0.021"/>
    <parent link="follower_left_camera_bottom_screw_frame"/>
    <child link="follower_left_camera_link"/>
  </joint>
  <link name="follower_left_camera_link">
    <visual>
      <!-- the mesh origin is at front plate in between the two infrared camera axes -->
      <origin rpy="1.5707963267948966 0 1.5707963267948966" xyz="0.0038 -0.009 0"/>
      <geometry>
        <mesh filename="package://trossen_arm_description/meshes/peripherals/d405.stl" scale="0.001 0.001 0.001"/>
      </geometry>
      <material name="aluminum">
        <color rgba="0.5 0.5 0.5 1"/>
      </material>
    </visual>
    <collision>
      <origin rpy="0 0 0" xyz="-0.0078 -0.009 0"/>
      <geometry>
        <box size="0.023 0.042 0.042"/>
      </geometry>
    </collision>
    <inertial>
      <!-- The following are not reliable values, and should not be used for modeling -->
      <mass value="0.072"/>
      <origin xyz="0 0 0"/>
      <inertia ixx="0.00002117" ixy="0.0" ixz="0.0" iyy="0.000013758" iyz="0.0" izz="0.000013758"/>
    </inertial>
  </link>
  <!-- camera depth joints and links -->
  <joint name="follower_left_camera_depth_joint" type="fixed">
    <origin rpy="0 0 0" xyz="0 0 0"/>
    <parent link="follower_left_camera_link"/>
    <child link="follower_left_camera_depth_frame"/>
  </joint>
  <link name="follower_left_camera_depth_frame"/>
  <joint name="follower_left_camera_depth_optical_joint" type="fixed">
    <origin rpy="-1.5707963267948966 0 -1.5707963267948966" xyz="0 0 0"/>
    <parent link="follower_left_camera_depth_frame"/>
    <child link="follower_left_camera_depth_optical_frame"/>
  </joint>
  <link name="follower_left_camera_depth_optical_frame"/>
  <!-- camera left IR joints and links -->
  <joint name="follower_left_camera_infra1_joint" type="fixed">
    <origin rpy="0 0 0" xyz="0 0.0 0"/>
    <parent link="follower_left_camera_link"/>
    <child link="follower_left_camera_infra1_frame"/>
  </joint>
  <link name="follower_left_camera_infra1_frame"/>
  <joint name="follower_left_camera_infra1_optical_joint" type="fixed">
    <origin rpy="-1.5707963267948966 0 -1.5707963267948966" xyz="0 0 0"/>
    <parent link="follower_left_camera_infra1_frame"/>
    <child link="follower_left_camera_infra1_optical_frame"/>
  </joint>
  <link name="follower_left_camera_infra1_optical_frame"/>
  <!-- camera right IR joints and links -->
  <joint name="follower_left_camera_infra2_joint" type="fixed">
    <origin rpy="0 0 0" xyz="0 -0.018 0"/>
    <parent link="follower_left_camera_link"/>
    <child link="follower_left_camera_infra2_frame"/>
  </joint>
  <link name="follower_left_camera_infra2_frame"/>
  <joint name="follower_left_camera_infra2_optical_joint" type="fixed">
    <origin rpy="-1.5707963267948966 0 -1.5707963267948966" xyz="0 0 0"/>
    <parent link="follower_left_camera_infra2_frame"/>
    <child link="follower_left_camera_infra2_optical_frame"/>
  </joint>
  <link name="follower_left_camera_infra2_optical_frame"/>
  <!-- camera color joints and links -->
  <joint name="follower_left_camera_color_joint" type="fixed">
    <origin rpy="0 0 0" xyz="0 0.0 0"/>
    <parent link="follower_left_camera_link"/>
    <child link="follower_left_camera_color_frame"/>
  </joint>
  <link name="follower_left_camera_color_frame"/>
  <joint name="follower_left_camera_color_optical_joint" type="fixed">
    <origin rpy="-1.5707963267948966 0 -1.5707963267948966" xyz="0 0 0"/>
    <parent link="follower_left_camera_color_frame"/>
    <child link="follower_left_camera_color_optical_frame"/>
  </joint>
  <link name="follower_left_camera_color_optical_frame"/>
  <!-- variant == 'follower' -->
  <!-- variant == 'leader' -->
  <link name="follower_left_gripper_left">
    <inertial>
      <origin rpy="0 0 0" xyz="0.01893993 -0.00901223 -0.00215453"/>
      <mass value="0.03090787"/>
      <inertia ixx="0.00000769" ixy="0.00000321" ixz="0.00000029" iyy="0.00001487" iyz="-0.00000020" izz="0.00001184"/>
    </inertial>
    <visual>
      <origin rpy="0 0 0" xyz="0 0 0"/>
      <geometry>
        <mesh filename="package://trossen_arm_description/meshes/wxai/gripper_left.stl"/>
      </geometry>
      <material name="trossen_black"/>
    </visual>
    <collision>
      <origin rpy="0 0 0" xyz="0 0 0"/>
      <geometry>
        <mesh filename="package://trossen_arm_description/meshes/wxai/gripper_left.stl"/>
      </geometry>
    </collision>
  </link>
  <joint name="follower_left_left_gripper_joint" type="fixed">
    <origin rpy="0 0 0" xyz="0 0 0"/>
    <parent link="follower_left_carriage_left"/>
    <child link="follower_left_gripper_left"/>
  </joint>
  <link name="follower_left_gripper_right">
    <inertial>
      <origin rpy="0 0 0" xyz="0.01893989 0.00901216 -0.00215461"/>
      <mass value="0.03090786"/>
      <inertia ixx="0.00000769" ixy="-0.00000321" ixz="0.00000029" iyy="0.00001487" iyz="0.00000020" izz="0.00001184"/>
    </inertial>
    <visual>
      <origin rpy="0 0 0" xyz="0 0 0"/>
      <geometry>
        <mesh filename="package://trossen_arm_description/meshes/wxai/gripper_right.stl"/>
      </geometry>
      <material name="trossen_black"/>
    </visual>
    <collision>
      <origin rpy="0 0 0" xyz="0 0 0"/>
      <geometry>
        <mesh filename="package://trossen_arm_description/meshes/wxai/gripper_right.stl"/>
      </geometry>
    </collision>
  </link>
  <joint name="follower_left_right_gripper_joint" type="fixed">
    <origin rpy="0 0 0" xyz="0 0 0"/>
    <parent link="follower_left_carriage_right"/>
    <child link="follower_left_gripper_right"/>
  </joint>
  <joint name="follower_left_ee_gripper" type="fixed">
    <origin rpy="0 0 0" xyz="0.156062 0 0"/>
    <parent link="follower_left_link_6"/>
    <child link="follower_left_ee_gripper_link"/>
  </joint>
  <link name="follower_left_ee_gripper_link"/>
  <!-- variant in ('base', 'follower') -->
  <joint name="follower_right_mount_joint" type="fixed">
    <origin rpy="0 0 1.5707963267948966" xyz="-0.019982 -0.457500 0.019086"/>
    <parent link="frame_link"/>
    <child link="follower_right_base_link"/>
  </joint>
  <ros2_control name="TrossenArmHardwareInterface" type="system">
    <hardware>
      <plugin>mock_components/GenericSystem</plugin>
      <!-- ros2_control_hardware_type == 'mock_components' -->
      <!-- ros2_control_hardware_type == 'real' -->
    </hardware>
    <joint name="follower_right_joint_0">
      <command_interface name="position"/>
      <command_interface name="velocity"/>
      <command_interface name="external_effort"/>
      <state_interface name="position">
        <param name="initial_value">0.0</param>
      </state_interface>
      <state_interface name="velocity">
        <param name="initial_value">0.0</param>
      </state_interface>
      <state_interface name="effort">
        <param name="initial_value">0.0</param>
      </state_interface>
    </joint>
    <joint name="follower_right_joint_1">
      <command_interface name="position"/>
      <command_interface name="velocity"/>
      <command_interface name="external_effort"/>
      <state_interface name="position">
        <param name="initial_value">0.0</param>
      </state_interface>
      <state_interface name="velocity">
        <param name="initial_value">0.0</param>
      </state_interface>
      <state_interface name="effort">
        <param name="initial_value">0.0</param>
      </state_interface>
    </joint>
    <joint name="follower_right_joint_2">
      <command_interface name="position"/>
      <command_interface name="velocity"/>
      <command_interface name="external_effort"/>
      <state_interface name="position">
        <param name="initial_value">0.0</param>
      </state_interface>
      <state_interface name="velocity">
        <param name="initial_value">0.0</param>
      </state_interface>
      <state_interface name="effort">
        <param name="initial_value">0.0</param>
      </state_interface>
    </joint>
    <joint name="follower_right_joint_3">
      <command_interface name="position"/>
      <command_interface name="velocity"/>
      <command_interface name="external_effort"/>
      <state_interface name="position">
        <param name="initial_value">0.0</param>
      </state_interface>
      <state_interface name="velocity">
        <param name="initial_value">0.0</param>
      </state_interface>
      <state_interface name="effort">
        <param name="initial_value">0.0</param>
      </state_interface>
    </joint>
    <joint name="follower_right_joint_4">
      <command_interface name="position"/>
      <command_interface name="velocity"/>
      <command_interface name="external_effort"/>
      <state_interface name="position">
        <param name="initial_value">0.0</param>
      </state_interface>
      <state_interface name="velocity">
        <param name="initial_value">0.0</param>
      </state_interface>
      <state_interface name="effort">
        <param name="initial_value">0.0</param>
      </state_interface>
    </joint>
    <joint name="follower_right_joint_5">
      <command_interface name="position"/>
      <command_interface name="velocity"/>
      <command_interface name="external_effort"/>
      <state_interface name="position">
        <param name="initial_value">0.0</param>
      </state_interface>
      <state_interface name="velocity">
        <param name="initial_value">0.0</param>
      </state_interface>
      <state_interface name="effort">
        <param name="initial_value">0.0</param>
      </state_interface>
    </joint>
    <joint name="follower_right_left_carriage_joint">
      <command_interface name="position"/>
      <command_interface name="velocity"/>
      <command_interface name="external_effort"/>
      <state_interface name="position">
        <param name="initial_value">0.0</param>
      </state_interface>
      <state_interface name="velocity">
        <param name="initial_value">0.0</param>
      </state_interface>
      <state_interface name="effort">
        <param name="initial_value">0.0</param>
      </state_interface>
    </joint>
  </ros2_control>
  <link name="follower_right_base_link">
    <inertial>
      <origin rpy="0 0 0" xyz="-0.00014175 -0.00005228 0.03175177"/>
      <mass value="0.45969858"/>
      <inertia ixx="0.00041660" ixy="0.00000011" ixz="-0.00000454" iyy="0.00044896" iyz="-0.00000078" izz="0.00021403"/>
    </inertial>
    <visual>
      <origin rpy="0 0 0" xyz="0 0 0"/>
      <geometry>
        <mesh filename="package://trossen_arm_description/meshes/wxai/base_link.stl"/>
      </geometry>
      <material name="trossen_black"/>
    </visual>
    <collision>
      <origin rpy="0 0 0" xyz="0 0 0"/>
      <geometry>
        <mesh filename="package://trossen_arm_description/meshes/wxai/base_link.stl"/>
      </geometry>
    </collision>
  </link>
  <link name="follower_right_link_1">
    <inertial>
      <origin rpy="0 0 0" xyz="-0.00011075 0.00171176 0.02044592"/>
      <mass value="0.15270428"/>
      <inertia ixx="0.00018509" ixy="-0.00000191" ixz="-0.00001436" iyy="0.00008358" iyz="-0.00000130" izz="0.00019219"/>
    </inertial>
    <visual>
      <origin rpy="0 0 0" xyz="0 0 0"/>
      <geometry>
        <mesh filename="package://trossen_arm_description/meshes/wxai/link_1.stl"/>
      </geometry>
      <material name="trossen_black"/>
    </visual>
    <collision>
      <origin rpy="0 0 0" xyz="0 0 0"/>
      <geometry>
        <mesh filename="package://trossen_arm_description/meshes/wxai/link_1.stl"/>
      </geometry>
    </collision>
  </link>
  <joint name="follower_right_joint_0" type="revolute">
    <origin rpy="0 0 0" xyz="0 0 0.05725"/>
    <parent link="follower_right_base_link"/>
    <child link="follower_right_link_1"/>
    <axis xyz="0 0 1"/>
    <limit effort="27.0" lower="-3.0543261909900767" upper="3.0543261909900767" velocity="3.375"/>
  </joint>
  <link name="follower_right_link_2">
    <inertial>
      <origin rpy="0 0 0" xyz="-0.13121451 -0.00292583 0.00021345"/>
      <mass value="1.15316319"/>
      <inertia ixx="0.00102632" ixy="-0.00000319" ixz="-0.00002679" iyy="0.01736118" iyz="-0.00000193" izz="0.01794489"/>
    </inertial>
    <visual>
      <origin rpy="0 0 0" xyz="0 0 0"/>
      <geometry>
        <mesh filename="package://trossen_arm_description/meshes/wxai/link_2.stl"/>
      </geometry>
      <material name="trossen_black"/>
    </visual>
    <collision>
      <origin rpy="0 0 0" xyz="0 0 0"/>
      <geometry>
        <mesh filename="package://trossen_arm_description/meshes/wxai/link_2.stl"/>
      </geometry>
    </collision>
  </link>
  <joint name="follower_right_joint_1" type="revolute">
    <origin rpy="0 0 0" xyz="0.02 0 0.04625"/>
    <parent link="follower_right_link_1"/>
    <child link="follower_right_link_2"/>
    <axis xyz="0 1 0"/>
    <limit effort="27.0" lower="0.0" upper="3.141592653589793" velocity="3.375"/>
  </joint>
  <link name="follower_right_link_3">
    <inertial>
      <origin rpy="0 0 0" xyz="0.18083602 -0.00094090 0.05554937"/>
      <mass value="0.68666638"/>
      <inertia ixx="0.00064876" ixy="0.00009128" ixz="-0.00052002" iyy="0.00547407" iyz="0.00001159" izz="0.00561509"/>
    </inertial>
    <visual>
      <origin rpy="0 0 0" xyz="0 0 0"/>
      <geometry>
        <mesh filename="package://trossen_arm_description/meshes/wxai/link_3.stl"/>
      </geometry>
      <material name="trossen_black"/>
    </visual>
    <collision>
      <origin rpy="0 0 0" xyz="0 0 0"/>
      <geometry>
        <mesh filename="package://trossen_arm_description/meshes/wxai/link_3.stl"/>
      </geometry>
    </collision>
  </link>
  <joint name="follower_right_joint_2" type="revolute">
    <origin rpy="0 0 0" xyz="-0.264 0 0"/>
    <parent link="follower_right_link_2"/>
    <child link="follower_right_link_3"/>
    <axis xyz="0 -1 0"/>
    <limit effort="27.0" lower="0.0" upper="2.356194490192345" velocity="3.375"/>
  </joint>
  <link name="follower_right_link_4">
    <inertial>
      <origin rpy="0 0 0" xyz="0.05797842 0.00027145 0.05884447"/>
      <mass value="0.45789905"/>
      <inertia ixx="0.00053839" ixy="0.00000690" ixz="-0.00018164" iyy="0.00066138" iyz="0.00000724" izz="0.00042116"/>
    </inertial>
    <visual>
      <origin rpy="0 0 0" xyz="0 0 0"/>
      <geometry>
        <mesh filename="package://trossen_arm_description/meshes/wxai/link_4.stl"/>
      </geometry>
      <material name="trossen_black"/>
    </visual>
    <collision>
      <origin rpy="0 0 0" xyz="0 0 0"/>
      <geometry>
        <mesh filename="package://trossen_arm_description/meshes/wxai/link_4.stl"/>
      </geometry>
    </collision>
  </link>
  <joint name="follower_right_joint_3" type="revolute">
    <origin rpy="0 0 0" xyz="0.245 0 0.06"/>
    <parent link="follower_right_link_3"/>
    <child link="follower_right_link_4"/>
    <axis xyz="0 -1 0"/>
    <limit effort="7.0" lower="-1.5707963267948966" upper="1.5707963267948966" velocity="7.0"/>
  </joint>
  <link name="follower_right_link_5">
    <inertial>
      <origin rpy="0 0 0" xyz="0.00412447 -0.00001138 -0.04283184"/>
      <mass value="0.36693910"/>
      <inertia ixx="0.00018912" ixy="-0.00000045" ixz="0.00000090" iyy="0.00032062" iyz="0.00000003" izz="0.00026750"/>
    </inertial>
    <visual>
      <origin rpy="0 0 0" xyz="0 0 0"/>
      <geometry>
        <mesh filename="package://trossen_arm_description/meshes/wxai/link_5.stl"/>
      </geometry>
      <material name="trossen_black"/>
    </visual>
    <collision>
      <origin rpy="0 0 0" xyz="0 0 0"/>
      <geometry>
        <mesh filename="package://trossen_arm_description/meshes/wxai/link_5.stl"/>
      </geometry>
    </collision>
  </link>
  <joint name="follower_right_joint_4" type="revolute">
    <origin rpy="0 0 0" xyz="0.06775 0 0.0455"/>
    <parent link="follower_right_link_4"/>
    <child link="follower_right_link_5"/>
    <axis xyz="0 0 -1"/>
    <limit effort="7.0" lower="-1.5707963267948966" upper="1.5707963267948966" velocity="7.0"/>
  </joint>
  <link name="follower_right_link_6">
    <inertial>
      <origin rpy="0 0 0" xyz="0.04572768 -0.00000726 0.00001402"/>
      <mass value="0.55469347"/>
      <inertia ixx="0.00082429" ixy="-0.00000051" ixz="0.00000010" iyy="0.00048759" iyz="0.00000004" izz="0.00108600"/>
    </inertial>
    <visual>
      <origin rpy="0 0 0" xyz="0 0 0"/>
      <geometry>
        <mesh filename="package://trossen_arm_description/meshes/wxai/link_6.stl"/>
      </geometry>
      <material name="trossen_black"/>
    </visual>
    <collision>
      <origin rpy="0 0 0" xyz="0 0 0"/>
      <geometry>
        <mesh filename="package://trossen_arm_description/meshes/wxai/link_6.stl"/>
      </geometry>
    </collision>
  </link>
  <joint name="follower_right_joint_5" type="revolute">
    <origin rpy="0 0 0" xyz="0.02895 0 -0.0455"/>
    <parent link="follower_right_link_5"/>
    <child link="follower_right_link_6"/>
    <axis xyz="1 0 0"/>
    <limit effort="7.0" lower="-3.141592653589793" upper="3.141592653589793" velocity="7.0"/>
  </joint>
  <link name="follower_right_carriage_right">
    <inertial>
      <origin rpy="0 0 0" xyz="-0.00889602 0.00403514 0.00457901"/>
      <mass value="0.05036313"/>
      <inertia ixx="0.00001736" ixy="-0.00000165" ixz="-0.00000104" iyy="0.00000591" iyz="-0.00000172" izz="0.00001378"/>
    </inertial>
    <visual>
      <origin rpy="0 0 0" xyz="0 0 0"/>
      <geometry>
        <mesh filename="package://trossen_arm_description/meshes/wxai/carriage_right.stl"/>
      </geometry>
      <material name="trossen_black"/>
    </visual>
    <collision>
      <origin rpy="0 0 0" xyz="0 0 0"/>
      <geometry>
        <mesh filename="package://trossen_arm_description/meshes/wxai/carriage_right.stl"/>
      </geometry>
    </collision>
  </link>
  <joint name="follower_right_right_carriage_joint" type="prismatic">
    <origin rpy="0 0 0" xyz="0.0865 -0.023 0"/>
    <parent link="follower_right_link_6"/>
    <child link="follower_right_carriage_right"/>
    <mimic joint="follower_right_left_carriage_joint"/>
    <axis xyz="0 -1 0"/>
    <limit effort="400.0" lower="0.0" upper="0.044" velocity="0.0875"/>
  </joint>
  <link name="follower_right_carriage_left">
    <inertial>
      <origin rpy="0 0 0" xyz="-0.00889602 -0.00403515 -0.00457908"/>
      <mass value="0.05036313"/>
      <inertia ixx="0.00001736" ixy="-0.00000165" ixz="-0.00000104" iyy="0.00000591" iyz="-0.00000172" izz="0.00001378"/>
    </inertial>
    <visual>
      <origin rpy="0 0 0" xyz="0 0 0"/>
      <geometry>
        <mesh filename="package://trossen_arm_description/meshes/wxai/carriage_left.stl"/>
      </geometry>
      <material name="trossen_black"/>
    </visual>
    <collision>
      <origin rpy="0 0 0" xyz="0 0 0"/>
      <geometry>
        <mesh filename="package://trossen_arm_description/meshes/wxai/carriage_left.stl"/>
      </geometry>
    </collision>
  </link>
  <joint name="follower_right_left_carriage_joint" type="prismatic">
    <origin rpy="0 0 0" xyz="0.0865 0.023 0"/>
    <parent link="follower_right_link_6"/>
    <child link="follower_right_carriage_left"/>
    <axis xyz="0 1 0"/>
    <limit effort="400.0" lower="0.0" upper="0.044" velocity="0.0875"/>
  </joint>
  <link name="follower_right_camera_mount_d405">
    <inertial>
      <origin rpy="0 0 0" xyz="0.03023383 0.00679835 0.05006687"/>
      <mass value="0.04518012"/>
      <inertia ixx="0.00003426" ixy="-0.00000027" ixz="-0.00000309" iyy="0.00001980" iyz="-0.00000319" izz="0.00002470"/>
    </inertial>
    <visual>
      <origin rpy="0 0 0" xyz="0 0 0"/>
      <geometry>
        <mesh filename="package://trossen_arm_description/meshes/wxai/camera_mount_d405.stl"/>
      </geometry>
      <material name="trossen_black"/>
    </visual>
    <collision>
      <origin rpy="0 0 0" xyz="0 0 0"/>
      <geometry>
        <mesh filename="package://trossen_arm_description/meshes/wxai/camera_mount_d405.stl"/>
      </geometry>
    </collision>
  </link>
  <joint name="follower_right_camera_mount_joint" type="fixed">
    <origin rpy="0 0 0" xyz="0.012 0 0"/>
    <parent link="follower_right_link_6"/>
    <child link="follower_right_camera_mount_d405"/>
  </joint>
  <!-- camera body, with origin at bottom screw mount -->
  <joint name="follower_right_camera_joint" type="fixed">
    <origin rpy="0 0.3490658503988659 0" xyz="0.02927207801 0 0.03824951197"/>
    <parent link="follower_right_camera_mount_d405"/>
    <child link="follower_right_camera_bottom_screw_frame"/>
  </joint>
  <link name="follower_right_camera_bottom_screw_frame"/>
  <joint name="follower_right_camera_link_joint" type="fixed">
    <origin rpy="0 0 0" xyz="0.01085 0.009 0.021"/>
    <parent link="follower_right_camera_bottom_screw_frame"/>
    <child link="follower_right_camera_link"/>
  </joint>
  <link name="follower_right_camera_link">
    <visual>
      <!-- the mesh origin is at front plate in between the two infrared camera axes -->
      <origin rpy="1.5707963267948966 0 1.5707963267948966" xyz="0.0038 -0.009 0"/>
      <geometry>
        <mesh filename="package://trossen_arm_description/meshes/peripherals/d405.stl" scale="0.001 0.001 0.001"/>
      </geometry>
      <material name="aluminum">
        <color rgba="0.5 0.5 0.5 1"/>
      </material>
    </visual>
    <collision>
      <origin rpy="0 0 0" xyz="-0.0078 -0.009 0"/>
      <geometry>
        <box size="0.023 0.042 0.042"/>
      </geometry>
    </collision>
    <inertial>
      <!-- The following are not reliable values, and should not be used for modeling -->
      <mass value="0.072"/>
      <origin xyz="0 0 0"/>
      <inertia ixx="0.00002117" ixy="0.0" ixz="0.0" iyy="0.000013758" iyz="0.0" izz="0.000013758"/>
    </inertial>
  </link>
  <!-- camera depth joints and links -->
  <joint name="follower_right_camera_depth_joint" type="fixed">
    <origin rpy="0 0 0" xyz="0 0 0"/>
    <parent link="follower_right_camera_link"/>
    <child link="follower_right_camera_depth_frame"/>
  </joint>
  <link name="follower_right_camera_depth_frame"/>
  <joint name="follower_right_camera_depth_optical_joint" type="fixed">
    <origin rpy="-1.5707963267948966 0 -1.5707963267948966" xyz="0 0 0"/>
    <parent link="follower_right_camera_depth_frame"/>
    <child link="follower_right_camera_depth_optical_frame"/>
  </joint>
  <link name="follower_right_camera_depth_optical_frame"/>
  <!-- camera left IR joints and links -->
  <joint name="follower_right_camera_infra1_joint" type="fixed">
    <origin rpy="0 0 0" xyz="0 0.0 0"/>
    <parent link="follower_right_camera_link"/>
    <child link="follower_right_camera_infra1_frame"/>
  </joint>
  <link name="follower_right_camera_infra1_frame"/>
  <joint name="follower_right_camera_infra1_optical_joint" type="fixed">
    <origin rpy="-1.5707963267948966 0 -1.5707963267948966" xyz="0 0 0"/>
    <parent link="follower_right_camera_infra1_frame"/>
    <child link="follower_right_camera_infra1_optical_frame"/>
  </joint>
  <link name="follower_right_camera_infra1_optical_frame"/>
  <!-- camera right IR joints and links -->
  <joint name="follower_right_camera_infra2_joint" type="fixed">
    <origin rpy="0 0 0" xyz="0 -0.018 0"/>
    <parent link="follower_right_camera_link"/>
    <child link="follower_right_camera_infra2_frame"/>
  </joint>
  <link name="follower_right_camera_infra2_frame"/>
  <joint name="follower_right_camera_infra2_optical_joint" type="fixed">
    <origin rpy="-1.5707963267948966 0 -1.5707963267948966" xyz="0 0 0"/>
    <parent link="follower_right_camera_infra2_frame"/>
    <child link="follower_right_camera_infra2_optical_frame"/>
  </joint>
  <link name="follower_right_camera_infra2_optical_frame"/>
  <!-- camera color joints and links -->
  <joint name="follower_right_camera_color_joint" type="fixed">
    <origin rpy="0 0 0" xyz="0 0.0 0"/>
    <parent link="follower_right_camera_link"/>
    <child link="follower_right_camera_color_frame"/>
  </joint>
  <link name="follower_right_camera_color_frame"/>
  <joint name="follower_right_camera_color_optical_joint" type="fixed">
    <origin rpy="-1.5707963267948966 0 -1.5707963267948966" xyz="0 0 0"/>
    <parent link="follower_right_camera_color_frame"/>
    <child link="follower_right_camera_color_optical_frame"/>
  </joint>
  <link name="follower_right_camera_color_optical_frame"/>
  <!-- variant == 'follower' -->
  <!-- variant == 'leader' -->
  <link name="follower_right_gripper_left">
    <inertial>
      <origin rpy="0 0 0" xyz="0.01893993 -0.00901223 -0.00215453"/>
      <mass value="0.03090787"/>
      <inertia ixx="0.00000769" ixy="0.00000321" ixz="0.00000029" iyy="0.00001487" iyz="-0.00000020" izz="0.00001184"/>
    </inertial>
    <visual>
      <origin rpy="0 0 0" xyz="0 0 0"/>
      <geometry>
        <mesh filename="package://trossen_arm_description/meshes/wxai/gripper_left.stl"/>
      </geometry>
      <material name="trossen_black"/>
    </visual>
    <collision>
      <origin rpy="0 0 0" xyz="0 0 0"/>
      <geometry>
        <mesh filename="package://trossen_arm_description/meshes/wxai/gripper_left.stl"/>
      </geometry>
    </collision>
  </link>
  <joint name="follower_right_left_gripper_joint" type="fixed">
    <origin rpy="0 0 0" xyz="0 0 0"/>
    <parent link="follower_right_carriage_left"/>
    <child link="follower_right_gripper_left"/>
  </joint>
  <link name="follower_right_gripper_right">
    <inertial>
      <origin rpy="0 0 0" xyz="0.01893989 0.00901216 -0.00215461"/>
      <mass value="0.03090786"/>
      <inertia ixx="0.00000769" ixy="-0.00000321" ixz="0.00000029" iyy="0.00001487" iyz="0.00000020" izz="0.00001184"/>
    </inertial>
    <visual>
      <origin rpy="0 0 0" xyz="0 0 0"/>
      <geometry>
        <mesh filename="package://trossen_arm_description/meshes/wxai/gripper_right.stl"/>
      </geometry>
      <material name="trossen_black"/>
    </visual>
    <collision>
      <origin rpy="0 0 0" xyz="0 0 0"/>
      <geometry>
        <mesh filename="package://trossen_arm_description/meshes/wxai/gripper_right.stl"/>
      </geometry>
    </collision>
  </link>
  <joint name="follower_right_right_gripper_joint" type="fixed">
    <origin rpy="0 0 0" xyz="0 0 0"/>
    <parent link="follower_right_carriage_right"/>
    <child link="follower_right_gripper_right"/>
  </joint>
  <joint name="follower_right_ee_gripper" type="fixed">
    <origin rpy="0 0 0" xyz="0.156062 0 0"/>
    <parent link="follower_right_link_6"/>
    <child link="follower_right_ee_gripper_link"/>
  </joint>
  <link name="follower_right_ee_gripper_link"/>
  <!-- variant in ('base', 'follower') -->
</robot>
